<!-- ======================================================
    Model       :: Tetris
        Source      : Manipulator and Manipulation in High Dimensional Spaces. Vikash Kumar, Ph.D. Thesis, CSE, Univ. of Washington. 2016.
        Publication : MuJoCo HAPTIX: A Virtual Reality System for Hand Manipulation. Vikash Kumar and Emanuel Todorov. IEEE-RAS International Conference on Humanoid Robots 2015

    Mujoco      :: Advanced physics simulation engine
        Source      : www.roboti.us
        Version     : 1.40
        Released    : 17Jan'17

    Author      :: Vikash Kumar
        Contacts    : vikash@cs.washington.edu
        Last edits  : 17Jan'17

    Copyright   :: Vikash Kumar
        Licensed under Apache License, Version 2.0 (the "License"); you may not use this file except in compliance with the License. You may obtain a copy of the License at http://www.apache.org/licenses/LICENSE-2.0 Unless required by applicable law or agreed to in writing, software distributed under the License is distributed on an "AS IS" BASIS, WITHOUT WARRANTIES OR CONDITIONS OF ANY KIND, either express or implied. See the License for the specific language governing permissions and limitations under the License.
====================================================== -->
<mujoco model="tetris">

    <compiler angle='radian' coordinate='local'/>

    <asset>
        <texture name="texTet" type="cube" builtin="flat" mark="cross" width="127" height="127"
            markrgb="0 0 0" random="0.01"/>
        <material name='matTet' texture="texTet" texuniform="false"/>
    </asset>

    <default>
        <default class="tetris">
            <geom type="box" material="matTet" condim="3"/>
        </default>
        <default class="target">
            <geom type="box" contype="0" conaffinity="0" group='3'/>
        </default>
    </default>

    <include file='../utils/basic_scene.xml'/>
    <worldbody>

    <body pos='0 0 0.02' euler='1.57 0 0'>
        <body pos="0 0 0.04" childclass="tetris">
            <geom name="dc" pos="0 0 -.02" type="box" size="0.060 0.020 0.020" rgba="0 1 0 1"/>
            <geom name="cc" pos="0 0 .02" type="box" size="0.020 0.020 0.020" rgba="0 1 0 1"/>
            <joint type='slide' axis='1 0 0' range='-1 1'/>
            <joint type='slide' axis='0 1 0' range='-1 1'/>
            <joint type='slide' axis='0 0 1' range='-1 1'/>
            <joint type='hinge' axis='1 0 0' limited='false'/>
            <joint type='hinge' axis='0 1 0' limited='false'/>
            <joint type='hinge' axis='0 0 1' limited='false'/>
        </body>
        <body pos="0 0 0.04" childclass="target">
            <geom name="dc1" pos="0 0 -.02" type="box" size="0.060 0.020 0.020" rgba="0 1 0 .2"/>
            <geom name="cc1" pos="0 0 .02" type="box" size="0.020 0.020 0.020" rgba="0 1 0 .2"/>
        </body>

        <body pos="0.06 0 0.06" euler='0 -1.57 0' childclass="tetris">
            <geom name="cd" pos="0 0 -.02" type="box" size="0.060 0.020 0.020" rgba="0 0 1 1"/>
            <geom name="ce" pos="0 0 .02" type="box" size="0.020 0.020 0.020" rgba="0 0 1 1"/>
            <joint type='slide' axis='1 0 0' range='-1 1'/>
            <joint type='slide' axis='0 1 0' range='-1 1'/>
            <joint type='slide' axis='0 0 1' range='-1 1'/>
            <joint type='hinge' axis='1 0 0' limited='false'/>
            <joint type='hinge' axis='0 1 0' limited='false'/>
            <joint type='hinge' axis='0 0 1' limited='false'/>
        </body>
        <body pos="0.06 0 0.06" euler='0 -1.57 0' childclass="target">
            <geom name="cd1" pos="0 0 -.02" type="box" size="0.060 0.020 0.020" rgba="0 0 1 .1"/>
            <geom name="ce1" pos="0 0 .02" type="box" size="0.020 0.020 0.020" rgba="0 0 1 .1"/>
        </body>

        <body pos="0.04 0 0.12" childclass="tetris">
            <geom name="bc" pos="-.02 0 -.02" type="box" size="0.040 0.020 0.020" rgba="1 0 0 1"/>
            <geom name="ad" pos="0.02 0 .02" type="box" size="0.040 0.020 0.020" rgba="1 0 0 1"/>
            <joint type='slide' axis='1 0 0' range='-1 1'/>
            <joint type='slide' axis='0 1 0' range='-1 1'/>
            <joint type='slide' axis='0 0 1' range='-1 1'/>
            <joint type='hinge' axis='1 0 0' limited='false'/>
            <joint type='hinge' axis='0 1 0' limited='false'/>
            <joint type='hinge' axis='0 0 1' limited='false'/>
        </body>

        <body pos="0.04 0 0.12" childclass="target">
            <geom name="bc1" pos="-.02 0 -.02" type="box" size="0.040 0.020 0.020" rgba="1 0 0 .2"/>
            <geom name="ad1" pos="0.02 0 .02" type="box" size="0.040 0.020 0.020" rgba="1 0 0 .2"/>
        </body>

        <body pos="-.06 0 0.06" euler='0 1.57 0' childclass="tetris">
            <geom name="ca" pos=".02 0 -.02" type="box" size="0.040 0.020 0.020" rgba="1 1 0 1"/>
            <geom name="cb" pos="-.02 0 .02" type="box" size="0.040 0.020 0.020" rgba="1 1 0 1"/>
            <joint type='slide' axis='1 0 0' range='-1 1'/>
            <joint type='slide' axis='0 1 0' range='-1 1'/>
            <joint type='slide' axis='0 0 1' range='-1 1'/>
            <joint type='hinge' axis='1 0 0' limited='false'/>
            <joint type='hinge' axis='0 1 0' limited='false'/>
            <joint type='hinge' axis='0 0 1' limited='false'/>
        </body>

        <body pos="-.06 0 0.06" euler='0 1.57 0' childclass="target">
            <geom name="ca1" pos="0.02 0 -.02" type="box" size="0.040 0.020 0.020" rgba="1 1 0 .2"/>
            <geom name="cb1" pos="-.02 0 .02" type="box" size="0.040 0.020 0.020" rgba="1 1 0 .2"/>
        </body>

        <body pos="-.04 0 .12" euler='0 3.14 0' childclass="tetris">
            <geom name="aa" pos=".04 0 .00" type="box" size="0.020 0.020 0.040" rgba="0 1 1 1"/>
            <geom name="ab" pos="-.02 0 -.02" type="box" size="0.040 0.020 0.020" rgba="0 1 1 1"/>
            <joint type='slide' axis='1 0 0' range='-1 1'/>
            <joint type='slide' axis='0 1 0' range='-1 1'/>
            <joint type='slide' axis='0 0 1' range='-1 1'/>
            <joint type='hinge' axis='1 0 0' limited='false'/>
            <joint type='hinge' axis='0 1 0' limited='false'/>
            <joint type='hinge' axis='0 0 1' limited='false'/>
        </body>
        <body pos="-.04 0 0.12" euler='0 3.14 0' childclass="target">
            <geom name="aa1" pos=".04 0 .00" type="box" size="0.020 0.020 0.040" rgba="0 1 1 .2"/>
            <geom name="ab1" pos="-.02 0 -.02" type="box" size="0.040 0.020 0.020" rgba="0 1 1 .2"/>
        </body>
    </body>

    </worldbody>
</mujoco>
