<!-- ======================================================
	Model 		:: Unicycle
 
	Mujoco		:: Advanced physics simulation engine
		Source		: www.roboti.us
		Version		: 1.50
		Released 	: 17Jan'17
		
	Author		:: Vikash Kumar
		Contacts 	: vikashplus@gmail.com
		Last edits 	: 24Oct'18

	Copyright 	:: Vikash Kumar
		Licensed under Apache License, Version 2.0 (the "License"); you may not use this file except in compliance with the License. You may obtain a copy of the License at http://www.apache.org/licenses/LICENSE-2.0 Unless required by applicable law or agreed to in writing, software distributed under the License is distributed on an "AS IS" BASIS, WITHOUT WARRANTIES OR CONDITIONS OF ANY KIND, either express or implied. See the License for the specific language governing permissions and limitations under the License.
====================================================== -->
<mujoco model='unicycle-v1.5'>
	
	<compiler inertiafromgeom='true' angle='degree' coordinate='local'/>
	<default>
		<joint limited='true' damping='1' armature='0' />
		<geom contype='1' condim='1' conaffinity='1' friction='.7 .01 .002' rgba='0.8 0.6 .4 1' margin='0.02' material="geom"/>
		<motor ctrlrange='-.3 .3'  ctrllimited='true'/>
	</default>

	<option timestep='0.002'/>

 	<visual>
        <map fogstart="3" fogend="5" force="0.1" znear="0.5"/>
        <quality shadowsize="2048" offsamples="8"/>
        <global offwidth="800" offheight="800"/>
    </visual>

    <asset>
        <texture name="skybox" type="skybox" builtin="gradient" rgb1=".08 .09 .10" rgb2="0 0 0"
               width="800" height="800" mark="random" markrgb=".8 .8 .8"/>
        <texture name="texgeom" type="cube" builtin="flat" mark="cross" width="127" height="1278" 
            rgb1="0.8 0.6 0.4" rgb2="0.8 0.6 0.4" markrgb="1 1 1" random="0.01"/>  
        <texture name="texplane" type="2d" builtin="checker" rgb1=".2 .3 .4" rgb2=".1 0.15 0.2" 
            width="512" height="512"/>  

        <material name='MatPlane' reflectance='0.3' texture="texplane" texrepeat="1 1" texuniform="true"/>
        <material name='geom' texture="texgeom" texuniform="true"/>
    </asset>

    <worldbody>
        <geom name='floor' pos='0 0 0' size='15 15 .125' type='plane' material="MatPlane" condim='3'/>

        <light mode='targetbodycom' target='torso' directional='false' diffuse='.8 .8 .8' specular='0.3 0.3 0.3' pos='0 0 4.0' dir='0 0 -1'/>

		<camera name='targeting' pos='1 1 2' mode='targetbodycom' target='torso'/>
		
        <site name='target' pos='0 0 0' size='.75 .001' type='cylinder' rgba='0.2 0.8 0.2 .3' />

		<body name='torso' pos='0 0 1.4'>
			<joint name='root' type='free' pos='0 0 0' limited='false' damping='0' armature='0'/>
			<geom name='torso1' type='capsule' fromto='0 -.07 0 0 .07 0'  size='0.07' />
			<geom name='head' type='sphere' pos='0 0 .19' size='.09' />
			<geom name='uwaist' type='capsule' fromto='0 -.06 -.12 0 .06 -.12'  size='0.06' />
			<body name='pelvis' pos='0 0 -0.425' quat='1.000 0 -0.002 0'>
				<joint name='abdomen_z' type='hinge' pos='0 0 0.22' axis='0 0 1' range='-45 45' damping='4' stiffness='10' armature='0.0069' />
				<joint name='abdomen_x' type='hinge' pos='0 0 0.22' axis='1 0 0' range='-20 20' damping='4' stiffness='5' armature='0.0153' />
				<joint name='abdomen_y' type='hinge' pos='0 0 0.22' axis='0 1 0' range='-60 30' damping='4' stiffness='5' armature='0.0077' />
				<geom name='lwaist' type='capsule' fromto='0 -.06 0.15 0 .06 0.15'  size='0.06' />
				<geom name='butt' type='capsule' fromto='-.02 -.03 0 -.02 .02 0'  size='0.09' />
				<body name='thigh' pos='0 0 -0.04' >
					<!-- <joint name='hip1' type='hinge' pos='0 0 0' axis='1 0 0' range='-25 5'   stiffness='10' armature='0.0268' damping='4'/> -->
					<joint name='hip2' type='hinge' pos='0 0 0' axis='0 0 1' range='-60 35'  stiffness='10' armature='0.02' damping='4'/>
					<joint name='hip3' type='hinge' pos='0 0 0' axis='0 1 0' range='-110 10' stiffness='20' armature='0.0080' damping='4'/>
					<geom name='thigh1' type='capsule' fromto='0 0 0 0 0.01 -.28'  size='0.065' />
					<body name='shin' pos='0 0.01 -0.37' >
						<joint name='knee' type='hinge' pos='0 0 .05' axis='0 -1 0' range='-160 -2' armature='0.0060' />
						<geom name='shin1' type='capsule' fromto='0 0 0 -.05 0 -.4'   size='0.049' />
						<joint name='yaw' type='hinge' pos='0 0 -.162' axis='0 0 1' range='-50 50' stiffness='1'  armature='0.0006' />
						<body name='wheel' pos='-0.05 0 -.4'>
							<joint name='wheel' type='hinge' pos='0 0 0' axis='0 1 0' limited='false' stiffness='0' armature='0' damping='0.1'/>
							<geom name='r_wheel' type='cylinder' fromto='0 -.01 0    0 0.01 0'  size='0.17' condim='6'/>
							<geom name='r_wheel0' type='cylinder' fromto='0 -.011 0    0 0.011 0'  size='0.12' rgba='0 0 0 1' contype='0' conaffinity='0' density='0'/>
							<geom name='r_decoration1' type='box'   size='0.15 0.012 0.02' contype='0' conaffinity='0' density='0'/>
							<geom name='r_decoration2' type='box'   size='0.02 0.012 0.15' contype='0' conaffinity='0' density='0'/>
						</body>
					</body>
				</body>
			</body>
			<body name='right_upper_arm' pos='0 -0.17 0.06' >
				<joint name='right_shoulder1' type='hinge' pos='0 0 0' axis='0 -1 1' range='-90 60' stiffness='1'  armature='0.0051' />
				<joint name='right_shoulder2' type='hinge' pos='0 0 0' axis='2 1 1'  range='-90 60' stiffness='1' armature='0.0068' />
				<geom name='right_uarm1' type='capsule' fromto='0 0 0 .16 -.16 -.16'  size='0.04 0.16' />
				<body name='right_lower_arm' pos='.18 -.18 -.18' >
					<joint name='right_elbow' type='hinge' pos='0 0 0' axis='0 -1 1' range='-90 50'  armature='0.0028' />
					<geom name='right_larm' type='capsule' fromto='0.02 0.02 0.02 .17 .17 .17'  size='0.031' />
					<geom name='right_hand' type='sphere' pos='.17 .17 .17'  size='0.04'/>
				</body>
			</body>
			<body name='left_upper_arm' pos='0 0.17 0.06' >
				<joint name='left_shoulder1' type='hinge' pos='0 0 0' axis='0 1 1' range='-60 90'  stiffness='1' armature='0.0051' />
				<joint name='left_shoulder2' type='hinge' pos='0 0 0' axis='2 -1 1' range='-60 90' stiffness='1' armature='0.0068' />
				<geom name='left_uarm1' type='capsule' fromto='0 0 0 .16 .16 -.16'  size='0.04 0.16' />
				<body name='left_lower_arm' pos='.18 .18 -.18' >
					<joint name='left_elbow' type='hinge' pos='0 0 0' axis='0 -1 -1' range='-90 50'  armature='0.0028' />
					<geom name='left_larm' type='capsule' fromto='0.02 -0.02 0.02 .17 -.17 .17'  size='0.031' />
					<geom name='left_hand' type='sphere' pos='.17 -.17 .17'  size='0.04'/>
				</body>
			</body>
		</body>
	</worldbody>

	<actuator>
		<motor name='a_abdomen_y' 			gear='200' joint='abdomen_y' />
		<motor name='a_abdomen_z' 			gear='200' joint='abdomen_z' />
		<motor name='a_abdomen_x' 			gear='200' joint='abdomen_x' />
		<motor name='a_right_hip2' 			gear='200' joint='hip2' />
		<motor name='a_right_hip3' 			gear='400' joint='hip3' />
		<motor name='a_right_knee' 			gear='400' joint='knee' />
		<motor name='a_right_ankle_x' 		gear='100' joint='yaw' />
		<motor name='a_right_ankle_y' 		gear='100' joint='wheel' />
		<motor name='a_right_shoulder1' 	gear='100' joint='right_shoulder1' />
		<motor name='a_right_shoulder2' 	gear='100' joint='right_shoulder2' />
		<motor name='a_right_elbow' 		gear='100' joint='right_elbow' />
		<motor name='a_left_shoulder1' 		gear='100' joint='left_shoulder1' />
		<motor name='a_left_shoulder2' 		gear='100' joint='left_shoulder2' />
		<motor name='a_left_elbow' 			gear='100' joint='left_elbow' />
	</actuator>
	
</mujoco>