<!-- ======================================================
	Model 		:: Slider
 
	Mujoco		:: Advanced physics simulation engine
		Source		: www.roboti.us
		Version		: 1.50
		Released 	: 17Jan'17
		
	Author		:: Vikash Kumar
		Contacts 	: vikashplus@gmail.com
		Last edits 	: 24Oct'18

	Copyright 	:: Vikash Kumar
		Licensed under Apache License, Version 2.0 (the "License"); you may not use this file except in compliance with the License. You may obtain a copy of the License at http://www.apache.org/licenses/LICENSE-2.0 Unless required by applicable law or agreed to in writing, software distributed under the License is distributed on an "AS IS" BASIS, WITHOUT WARRANTIES OR CONDITIONS OF ANY KIND, either express or implied. See the License for the specific language governing permissions and limitations under the License.
====================================================== -->
<mujoco model='slider-v1.5'>
    <compiler inertiafromgeom='true' angle='radian'/>

    <default>
        <joint limited='true' damping='0.01' armature='0' frictionloss='0.1' />
        <geom contype='1' conaffinity='1' condim='3' rgba='0.8 0.6 .4 1'
        	margin="0.001" solref=".02 1" solimp=".8 .8 .01" material="geom" density="50"/>
        <motor ctrlrange='-1 1'  ctrllimited='true'/>
    </default>

    <option timestep='0.002' iterations="50" solver="PGS">
        <flag energy="enable"/>
    </option>

    <visual>
        <map fogstart="3" fogend="5" force="0.1" znear="0.1"/>
        <quality shadowsize="2048"/>
        <global offwidth="800" offheight="800"/>
    </visual>

    <asset>
        <texture name="skybox" type="skybox" builtin="gradient" rgb1=".08 .09 .10" rgb2="0 0 0"
               width="800" height="800" mark="random" markrgb=".8 .8 .8"/>
        <texture name="texgeom" type="cube" builtin="flat" mark="cross" width="127" height="1278" markrgb="1 1 1" random="0.01"/>  
        <texture name="texplane" type="2d" builtin="checker" rgb1=".2 .3 .4" rgb2=".1 0.15 0.2" 
            width="512" height="512"/>  

        <material name='MatPlane' reflectance='0.5' texture="texplane" texrepeat="1 1" texuniform="true"/>
        <material name='geom' texture="texgeom" texuniform="true"/>
    </asset>

	
	
    <worldbody>     
        <light directional='true' diffuse='.8 .8 .8' specular='0.3 0.3 0.3' pos='0 -.15 1.0' dir='0 -.15 -1'/>
		<geom name='floor' pos='4 0 0' size='7 2 .125' conaffinity='0' contype='0' type='plane' material="MatPlane" condim='3'/>
		<geom name="track_boss" type="capsule" pos='0 0 .15' conaffinity='0' contype='0' size=".055 1" euler='0 1.57 0'/>		
		<geom name="track_worker" type="capsule" pos='4 0 .15' conaffinity='0' contype='0' size=".05 5" euler='0 1.57 0' rgba='.3 .8 .7 1'/>		
		<geom name="target" type="box" pos='6 0 .15' conaffinity='0' contype='0' size=".16 .16 .16" rgba='0 1 0 .4'/>		
		
		
		<body name='boss' pos='-.5 0 .15'>
			<geom name='ball' type='sphere' size='.15'/>
			<joint name='ballx' type='slide' axis='1 0 0' range='-.5 1.5'/>
		</body>
		
		<body name='worker' pos='0 0 .15'>
			<geom type='box' size='.15 .15 .15' rgba='.3 .8 .7 1'/>
			<joint name='workerx' type='slide' axis='1 0 0' limited='true' range='-1 9' frictionloss="2"/>
		</body>  
	</worldbody>

    <actuator>
		<motor name='bossx' 	gear='50' joint='ballx'/>
    </actuator>
	
	<sensor>
		<jointpos name="ballx"	joint="ballx"/>
	</sensor>

</mujoco>
