<!-- ==== Copyright | Vikash Kumar | vikashplus@gmail.com ====
    Model       :: Tetris
        Source      : Manipulator and Manipulation in High Dimensional Spaces. Vikash Kumar, Ph.D. Thesis, CSE, Univ. of Washington. 2016.
        Publication : MuJoCo HAPTIX: A Virtual Reality System for Hand Manipulation. Vikash Kumar and Emanuel Todorov. IEEE-RAS International Conference on Humanoid Robots 2015

    Mujoco      :: Advanced physics simulation engine
        Source      : www.roboti.us
        Version     : 1.50
        Released    : 17Jan'17

    Author      :: Vikash Kumar
        Contacts    : vikashplus@gmail.com
        Last edits  : 17Jan'17

    Copyright   :: Vikash Kumar
        Licensed under Apache License, Version 2.0 (the "License"); you may not use this file except in compliance with the License. You may obtain a copy of the License at http://www.apache.org/licenses/LICENSE-2.0 Unless required by applicable law or agreed to in writing, software distributed under the License is distributed on an "AS IS" BASIS, WITHOUT WARRANTIES OR CONDITIONS OF ANY KIND, either express or implied. See the License for the specific language governing permissions and limitations under the License.
=========================================================== -->

<mujoco model="Dice">

    <asset>
        <texture name='dice' file="dice.png" gridsize="3 4" gridlayout="..U.LFRB..D."/>
        <material name="MatDice" texture="dice" specular=".3" shininess="1" reflectance=".00001"/>
    </asset>

    <include file='../utils/basic_scene.xml'/>

    <worldbody>

        <body name="Object" pos="-0.00 -0.18 0.26" user="1001 0 2003 27 0 0 0.06 0 0">
            <inertial pos="0 0 0" mass="0.108" diaginertia="6.48e-05 6.48e-05 6.48e-05" />

            <geom pos='0 0 0' type="capsule" rgba='1 1 1 1' fromto=" 0.0235 -.0235 -.0235  .0235 .0235 -.0235" size=".0050"/>
            <geom pos='0 0 0' type="capsule" rgba='1 1 1 1' fromto="-.0235 -.0235 -.0235 -.0235 .0235 -.0235" size=".0050"/>
            <geom pos='0 0 0' type="capsule" rgba='1 1 1 1' fromto=" -.0235 .0235 -.0235  .0235 .0235 -.0235" size=".0050"/>
            <geom pos='0 0 0' type="capsule" rgba='1 1 1 1' fromto=" -.0235 -.0235 -.0235  .0235 -.0235 -.0235" size=".0050"/>
            <geom pos='0 0 0' type="capsule" rgba='1 1 1 1' fromto=" .0235 -.0235 .0235 .0235 .0235 .0235" size=".0050"/>
            <geom pos='0 0 0' type="capsule" rgba='1 1 1 1' fromto="-.0235 -.0235 .0235 -.0235 .0235 .0235" size=".0050"/>
            <geom pos='0 0 0' type="capsule" rgba='1 1 1 1' fromto=" -.0235 .0235 .0235  .0235 .0235 .0235" size=".0050"/>
            <geom pos='0 0 0' type="capsule" rgba='1 1 1 1' fromto=" -.0235 -.0235 .0235  .0235 -.0235 .0235" size=".0050"/>
            <geom pos='0 0 0' type="capsule" rgba='1 1 1 1' fromto=".0235 -.0235 -.0235  .0235 -.0235 .0235" size=".0050"/>
            <geom pos='0 0 0' type="capsule" rgba='1 1 1 1' fromto=".0235 .0235 -.0235  .0235 .0235 .0235" size=".0050"/>
            <geom pos='0 0 0' type="capsule" rgba='1 1 1 1' fromto="-.0235 .0235 -.0235  -.0235 .0235 .0235" size=".0050"/>
            <geom pos='0 0 0' type="capsule" rgba='1 1 1 1' fromto="-.0235 -.0235 -.0235  -.0235 -.0235 .0235" size=".0050"/>

            <geom type="box" size=".0284 .0236 .0236" material="MatDice"/>
            <geom type="box" size=".0236 .0284 .0236" material="MatDice"/>
            <geom type="box" size=".0236 .0236 .0284" material="MatDice"/>

            <joint name="OBJTx" pos="0 0 0" axis="1 0 0" type="slide" range="-.5 .5" damping="0.001" />
            <joint name="OBJTy" pos="0 0 0" axis="0 1 0" type="slide" range="-.5 .5" damping="0.001" />
            <joint name="OBJTz" pos="0 0 0" axis="0 0 1" type="slide" range="-.5 .5" damping="0.001" />
            <joint name="OBJRx" pos="0 0 0  " axis="1 0 0" limited="false" damping="0.001" />
            <joint name="OBJRy" pos="0 0 0" axis="0 1 0" limited="false" damping="0.001" />
            <joint name="OBJRz" pos="0 0 0" axis="0 0 1" limited="false" damping="0.001" />

            <!-- <geom name="dice" type="box" size="0.0284 0.0284 0.0284" condim="4" material="MatDice"/> -->
            <site name="object_o" type="sphere" size="0.005" rgba="0.8 0.8 0.8 0.8" group="4" pos="0 0 0" />
            <site name="object_x" type="sphere" size="0.005" rgba="0.8 0.2 0.2 0.8" group="4" pos="0.028 0 0" />
            <site name="object_y" type="sphere" size="0.005" rgba="0.2 0.8 0.2 0.8" group="4" pos="0 .028 0" />
            <site name="object_z" type="sphere" size="0.005" rgba="0.2 0.2 0.8 0.8" group="4" pos="0 0 .028" />

        </body>

        <body name="target" pos="0.2 -0.18 0.25" >
            <geom name="target_dice" type="box" size="0.026 0.026 0.026" contype="0" conaffinity="0" material="MatDice" rgba='1 1 1 .3'/>
            <site name="target_ball" type="sphere" size="0.07" rgba="0.2 0.7 0.2 0.1"/>
            <site name="target_o" type="sphere" size="0.005" rgba="0.8 0.8 0.8 0.8" group="4" pos="0 0 0" />
            <site name="target_x" type="sphere" size="0.005" rgba="0.8 0.2 0.2 0.8" group="4" pos="0.03 0 0" />
            <site name="target_y" type="sphere" size="0.005" rgba="0.2 0.8 0.2 0.8" group="4" pos="0 .03 0" />
            <site name="target_z" type="sphere" size="0.005" rgba="0.2 0.2 0.8 0.8" group="4" pos="0 0 .03" />
        </body>
    </worldbody>

</mujoco>
